2021-04-06 16:46:47,369 INFO    MainThread:187476 [wandb_init.py:_log_setup():292] Logging user logs to /home/menglh/rlproj/tmp/on-policy/onpolicy/scripts/results/StarCraft2/corridor/mappo/mlp/wandb/run-20210406_164647-2dqz30er/logs/debug.log
2021-04-06 16:46:47,370 INFO    MainThread:187476 [wandb_init.py:_log_setup():293] Logging internal logs to /home/menglh/rlproj/tmp/on-policy/onpolicy/scripts/results/StarCraft2/corridor/mappo/mlp/wandb/run-20210406_164647-2dqz30er/logs/debug-internal.log
2021-04-06 16:46:47,370 INFO    MainThread:187476 [wandb_setup.py:_flush():68] setting env: {}
2021-04-06 16:46:47,370 INFO    MainThread:187476 [wandb_setup.py:_flush():68] setting user settings: {}
2021-04-06 16:46:47,370 INFO    MainThread:187476 [wandb_setup.py:_flush():68] multiprocessing start_methods=fork,spawn,forkserver
2021-04-06 16:46:48,792 WARNING MainThread:187476 [wandb_init.py:init():483] interrupted
Traceback (most recent call last):
  File "/home/menglh/miniconda3/envs/ob_mappo/lib/python3.6/site-packages/wandb/sdk/wandb_init.py", line 463, in init
    run = wi.init()
  File "/home/menglh/miniconda3/envs/ob_mappo/lib/python3.6/site-packages/wandb/sdk/wandb_init.py", line 366, in init
    ret = backend.interface.communicate_check_version()
  File "/home/menglh/miniconda3/envs/ob_mappo/lib/python3.6/site-packages/wandb/interface/interface.py", line 595, in communicate_check_version
    result = self._communicate(rec)
  File "/home/menglh/miniconda3/envs/ob_mappo/lib/python3.6/site-packages/wandb/interface/interface.py", line 437, in _communicate
    return future.get(timeout)
  File "/home/menglh/miniconda3/envs/ob_mappo/lib/python3.6/site-packages/wandb/interface/interface.py", line 58, in get
    is_set = self._object_ready.wait(timeout)
  File "/home/menglh/miniconda3/envs/ob_mappo/lib/python3.6/threading.py", line 551, in wait
    signaled = self._cond.wait(timeout)
  File "/home/menglh/miniconda3/envs/ob_mappo/lib/python3.6/threading.py", line 299, in wait
    gotit = waiter.acquire(True, timeout)
KeyboardInterrupt
2021-04-06 16:46:48,815 INFO    MainThread:187476 [internal.py:handle_exit():137] Internal process exited
